(2967807, 37)
Index(['Unnamed: 0', 'upc', 'dma_code', 'month', 'volume', 'price',
       'size1_amount', 'size1_units', 'brand_descr', 'owner initial',
       'owner last', 'y-m-d', 'year', '# month', 'market_size',
       'market_size_DMA', 'market_share', 'postmerger', 'month_since_start',
       'involved', 'involvedpostmerger', 'product-region', 'time', 'cpiu',
       'price_index', 'adjusted_price', 'log_adjusted_price',
       'hhinc_per_person_mean', 'hhinc_per_person_median', 'employment_rate',
       'adjusted_hhinc_per_person_mean', 'log_adjusted_hhinc_per_person_mean',
       'log_employment_rate', 'product', 'upc_dma_code', 'distance', 'y-m'],
      dtype='object')
Traceback (most recent call last):
  File "/home/yza4307/.local/lib/python3.6/site-packages/pandas/core/indexes/base.py", line 2897, in get_loc
    return self._engine.get_loc(key)
  File "pandas/_libs/index.pyx", line 107, in pandas._libs.index.IndexEngine.get_loc
  File "pandas/_libs/index.pyx", line 131, in pandas._libs.index.IndexEngine.get_loc
  File "pandas/_libs/hashtable_class_helper.pxi", line 1607, in pandas._libs.hashtable.PyObjectHashTable.get_item
  File "pandas/_libs/hashtable_class_helper.pxi", line 1614, in pandas._libs.hashtable.PyObjectHashTable.get_item
KeyError: 'style_descr'

During handling of the above exception, another exception occurred:

Traceback (most recent call last):
  File "GenerateDemandEstimationData.py", line 138, in <module>
    GenerateDEData(product, frequency,['wheat','barley'], ['style_descr'], start, end)
  File "GenerateDemandEstimationData.py", line 23, in GenerateDEData
    data['style_descr'] = np.where(data['style_descr'] == 'DOMESTIC', 0, 1)
  File "/home/yza4307/.local/lib/python3.6/site-packages/pandas/core/frame.py", line 2995, in __getitem__
    indexer = self.columns.get_loc(key)
  File "/home/yza4307/.local/lib/python3.6/site-packages/pandas/core/indexes/base.py", line 2899, in get_loc
    return self._engine.get_loc(self._maybe_cast_indexer(key))
  File "pandas/_libs/index.pyx", line 107, in pandas._libs.index.IndexEngine.get_loc
  File "pandas/_libs/index.pyx", line 131, in pandas._libs.index.IndexEngine.get_loc
  File "pandas/_libs/hashtable_class_helper.pxi", line 1607, in pandas._libs.hashtable.PyObjectHashTable.get_item
  File "pandas/_libs/hashtable_class_helper.pxi", line 1614, in pandas._libs.hashtable.PyObjectHashTable.get_item
KeyError: 'style_descr'
